2020-10-23 23:02:39,977 INFO    MainThread:5608 [internal.py:wandb_internal():62] W&B internal server running at pid: 5608
2020-10-23 23:02:39,979 INFO    WriterThread:5608 [datastore.py:open_for_write():76] open: wandb\run-20201023_230239-2j3tepr0\run-2j3tepr0.wandb
2020-10-23 23:02:39,979 DEBUG   HandlerThread:5608 [handler.py:handle_request():54] handle_request: check_version
2020-10-23 23:02:39,984 DEBUG   SenderThread:5608 [sender.py:send():89] send: header
2020-10-23 23:02:39,984 DEBUG   SenderThread:5608 [sender.py:send():89] send: request
2020-10-23 23:02:39,984 DEBUG   SenderThread:5608 [sender.py:send_request():98] send_request: check_version
2020-10-23 23:02:39,986 DEBUG   Thread-8  :5608 [connectionpool.py:_new_conn():943] Starting new HTTPS connection (1): pypi.org:443
2020-10-23 23:02:40,560 DEBUG   Thread-8  :5608 [connectionpool.py:_make_request():442] https://pypi.org:443 "GET /pypi/wandb/json HTTP/1.1" 200 51107
2020-10-23 23:02:40,606 DEBUG   SenderThread:5608 [sender.py:send():89] send: run
2020-10-23 23:02:40,626 DEBUG   SenderThread:5608 [util.py:is_cygwin_git():315] Failed checking if running in CYGWIN due to: FileNotFoundError(2, 'El sistema no puede encontrar el archivo especificado', None, 2, None)
2020-10-23 23:02:40,629 DEBUG   SenderThread:5608 [cmd.py:execute():719] Popen(['git', 'cat-file', '--batch-check'], cwd=C:\Users\Eddili\Repos\Disert, universal_newlines=False, shell=None, istream=<valid stream>)
2020-10-23 23:02:40,664 DEBUG   SenderThread:5608 [connectionpool.py:_new_conn():943] Starting new HTTPS connection (1): api.wandb.ai:443
2020-10-23 23:02:40,960 DEBUG   SenderThread:5608 [connectionpool.py:_make_request():442] https://api.wandb.ai:443 "POST /graphql HTTP/1.1" 404 None
2020-10-23 23:02:40,962 ERROR   SenderThread:5608 [internal_api.py:execute():131] 404 response executing GraphQL.
2020-10-23 23:02:40,962 ERROR   SenderThread:5608 [internal_api.py:execute():132] {"errors":[{"message":"project mlclass/transfer learn not found","path":["upsertBucket"]}],"data":{"upsertBucket":null}}
2020-10-23 23:02:41,608 INFO    WriterThread:5608 [datastore.py:close():257] close: wandb\run-20201023_230239-2j3tepr0\run-2j3tepr0.wandb
2020-10-23 23:02:41,608 INFO    HandlerThread:5608 [handler.py:finish():267] shutting down handler
2020-10-23 23:02:41,608 ERROR   MainThread:5608 [internal.py:wandb_internal():128] Thread SenderThread:
Traceback (most recent call last):
  File "C:\Users\Eddili\anaconda3\envs\cpugputensorflow\lib\site-packages\wandb\old\retry.py", line 96, in __call__
    result = self._call_fn(*args, **kwargs)
  File "C:\Users\Eddili\anaconda3\envs\cpugputensorflow\lib\site-packages\wandb\internal\internal_api.py", line 134, in execute
    six.reraise(*sys.exc_info())
  File "C:\Users\Eddili\anaconda3\envs\cpugputensorflow\lib\site-packages\six.py", line 703, in reraise
    raise value
  File "C:\Users\Eddili\anaconda3\envs\cpugputensorflow\lib\site-packages\wandb\internal\internal_api.py", line 128, in execute
    return self.client.execute(*args, **kwargs)
  File "C:\Users\Eddili\anaconda3\envs\cpugputensorflow\lib\site-packages\wandb\vendor\gql-0.2.0\gql\client.py", line 52, in execute
    result = self._get_result(document, *args, **kwargs)
  File "C:\Users\Eddili\anaconda3\envs\cpugputensorflow\lib\site-packages\wandb\vendor\gql-0.2.0\gql\client.py", line 60, in _get_result
    return self.transport.execute(document, *args, **kwargs)
  File "C:\Users\Eddili\anaconda3\envs\cpugputensorflow\lib\site-packages\wandb\vendor\gql-0.2.0\gql\transport\requests.py", line 39, in execute
    request.raise_for_status()
  File "C:\Users\Eddili\anaconda3\envs\cpugputensorflow\lib\site-packages\requests\models.py", line 941, in raise_for_status
    raise HTTPError(http_error_msg, response=self)
requests.exceptions.HTTPError: 404 Client Error: Not Found for url: https://api.wandb.ai/graphql

During handling of the above exception, another exception occurred:

Traceback (most recent call last):
  File "C:\Users\Eddili\anaconda3\envs\cpugputensorflow\lib\site-packages\wandb\apis\normalize.py", line 24, in wrapper
    return func(*args, **kwargs)
  File "C:\Users\Eddili\anaconda3\envs\cpugputensorflow\lib\site-packages\wandb\internal\internal_api.py", line 974, in upsert_run
    response = self.gql(mutation, variable_values=variable_values, **kwargs)
  File "C:\Users\Eddili\anaconda3\envs\cpugputensorflow\lib\site-packages\wandb\old\retry.py", line 105, in __call__
    if not check_retry_fn(e):
  File "C:\Users\Eddili\anaconda3\envs\cpugputensorflow\lib\site-packages\wandb\util.py", line 602, in no_retry_auth
    raise CommError("Permission denied, ask the project owner to grant you access")
wandb.errors.error.CommError: Permission denied, ask the project owner to grant you access

During handling of the above exception, another exception occurred:

Traceback (most recent call last):
  File "C:\Users\Eddili\anaconda3\envs\cpugputensorflow\lib\site-packages\wandb\internal\internal_util.py", line 33, in run
    self._run()
  File "C:\Users\Eddili\anaconda3\envs\cpugputensorflow\lib\site-packages\wandb\internal\internal_util.py", line 60, in _run
    self._process(record)
  File "C:\Users\Eddili\anaconda3\envs\cpugputensorflow\lib\site-packages\wandb\internal\internal.py", line 232, in _process
    self._sm.send(record)
  File "C:\Users\Eddili\anaconda3\envs\cpugputensorflow\lib\site-packages\wandb\internal\sender.py", line 91, in send
    send_handler(record)
  File "C:\Users\Eddili\anaconda3\envs\cpugputensorflow\lib\site-packages\wandb\internal\sender.py", line 378, in send_run
    self._init_run(run, config_dict)
  File "C:\Users\Eddili\anaconda3\envs\cpugputensorflow\lib\site-packages\wandb\internal\sender.py", line 414, in _init_run
    commit=repo.last_commit,
  File "C:\Users\Eddili\anaconda3\envs\cpugputensorflow\lib\site-packages\wandb\apis\normalize.py", line 62, in wrapper
    six.reraise(CommError, CommError(message, err), sys.exc_info()[2])
  File "C:\Users\Eddili\anaconda3\envs\cpugputensorflow\lib\site-packages\six.py", line 702, in reraise
    raise value.with_traceback(tb)
  File "C:\Users\Eddili\anaconda3\envs\cpugputensorflow\lib\site-packages\wandb\apis\normalize.py", line 24, in wrapper
    return func(*args, **kwargs)
  File "C:\Users\Eddili\anaconda3\envs\cpugputensorflow\lib\site-packages\wandb\internal\internal_api.py", line 974, in upsert_run
    response = self.gql(mutation, variable_values=variable_values, **kwargs)
  File "C:\Users\Eddili\anaconda3\envs\cpugputensorflow\lib\site-packages\wandb\old\retry.py", line 105, in __call__
    if not check_retry_fn(e):
  File "C:\Users\Eddili\anaconda3\envs\cpugputensorflow\lib\site-packages\wandb\util.py", line 602, in no_retry_auth
    raise CommError("Permission denied, ask the project owner to grant you access")
wandb.errors.error.CommError: Permission denied, ask the project owner to grant you access
2020-10-23 23:02:41,626 DEBUG   raven-sentry.BackgroundWorker:5608 [connectionpool.py:_new_conn():943] Starting new HTTPS connection (1): o151352.ingest.sentry.io:443
2020-10-23 23:02:42,153 DEBUG   raven-sentry.BackgroundWorker:5608 [connectionpool.py:_make_request():442] https://o151352.ingest.sentry.io:443 "POST /api/5288891/store/ HTTP/1.1" 200 41
2020-10-23 23:02:43,625 INFO    MainThread:5608 [internal.py:handle_exit():137] Internal process exited
